2022-06-08 01:53:39,753 - 60868 - INFO - Fetching JSON data from sample_data.json
2022-06-08 01:53:39,753 - 60868 - INFO - Processing Activity Id : 1
2022-06-08 01:53:39,754 - 60868 - INFO - Processing Activity Id : 2
2022-06-08 01:53:39,754 - 60868 - ERROR - Activity Id : 2 - Activity Time must be an integer and greater than zero - !!Terminating Processing for this Activity ID!!
2022-06-08 01:53:39,754 - 60868 - INFO - Processing Activity Id : 3
2022-06-08 01:53:39,756 - 60868 - INFO - Processing Activity Id : 4
2022-06-08 01:53:39,756 - 60868 - ERROR - Activity Id : 4 - User ID cannot be empty - !!Terminating Processing for this Activity ID!!
2022-06-08 01:53:39,756 - 60868 - INFO - Processing Activity Id : 5
2022-06-08 01:53:39,772 - 60868 - ERROR - Activity Id : 3 - https://www.server_3.com/python/ - HTTPSConnectionPool(host='www.server_3.com', port=443): Max retries exceeded with url: /python/ (Caused by NewConnectionError('<urllib3.connection.HTTPSConnection object at 0x103263be0>: Failed to establish a new connection: [Errno 8] nodename nor servname provided, or not known'))
2022-06-08 01:53:39,772 - 60868 - ERROR - Activity Id : 1 - https://www.server_4.com/python/ - HTTPSConnectionPool(host='www.server_4.com', port=443): Max retries exceeded with url: /python/ (Caused by NewConnectionError('<urllib3.connection.HTTPSConnection object at 0x103263640>: Failed to establish a new connection: [Errno 8] nodename nor servname provided, or not known'))
2022-06-08 01:53:39,772 - 60868 - ERROR - Activity Id : 5 - https://www.server_1.com/python/ - HTTPSConnectionPool(host='www.server_1.com', port=443): Max retries exceeded with url: /python/ (Caused by NewConnectionError('<urllib3.connection.HTTPSConnection object at 0x103263dc0>: Failed to establish a new connection: [Errno 8] nodename nor servname provided, or not known'))
2022-06-08 01:53:39,772 - 60868 - ERROR - Activity Id : 3 - https://www.server_4.com/python/ - HTTPSConnectionPool(host='www.server_4.com', port=443): Max retries exceeded with url: /python/ (Caused by NewConnectionError('<urllib3.connection.HTTPSConnection object at 0x1032561c0>: Failed to establish a new connection: [Errno 8] nodename nor servname provided, or not known'))
2022-06-08 01:53:39,772 - 60868 - ERROR - Activity Id : 3 - https://www.server_5.com/python/ - HTTPSConnectionPool(host='www.server_5.com', port=443): Max retries exceeded with url: /python/ (Caused by NewConnectionError('<urllib3.connection.HTTPSConnection object at 0x1032563a0>: Failed to establish a new connection: [Errno 8] nodename nor servname provided, or not known'))
2022-06-08 01:53:39,773 - 60868 - ERROR - Activity Id : 1 - https://www.server_1.com/python/ - HTTPSConnectionPool(host='www.server_1.com', port=443): Max retries exceeded with url: /python/ (Caused by NewConnectionError('<urllib3.connection.HTTPSConnection object at 0x103257370>: Failed to establish a new connection: [Errno 8] nodename nor servname provided, or not known'))
2022-06-08 01:53:39,773 - 60868 - ERROR - Activity Id : 5 - https://www.server_2.com/python/ - HTTPSConnectionPool(host='www.server_2.com', port=443): Max retries exceeded with url: /python/ (Caused by NewConnectionError('<urllib3.connection.HTTPSConnection object at 0x103263460>: Failed to establish a new connection: [Errno 8] nodename nor servname provided, or not known'))
2022-06-08 01:53:39,773 - 60868 - ERROR - Activity Id : 3 - https://www.server_2.com/python/ - HTTPSConnectionPool(host='www.server_2.com', port=443): Max retries exceeded with url: /python/ (Caused by NewConnectionError('<urllib3.connection.HTTPSConnection object at 0x103257be0>: Failed to establish a new connection: [Errno 8] nodename nor servname provided, or not known'))
2022-06-08 01:53:39,773 - 60868 - ERROR - Activity Id : 5 - https://www.server_4.com/python/ - HTTPSConnectionPool(host='www.server_4.com', port=443): Max retries exceeded with url: /python/ (Caused by NewConnectionError('<urllib3.connection.HTTPSConnection object at 0x1032632b0>: Failed to establish a new connection: [Errno 8] nodename nor servname provided, or not known'))
2022-06-08 01:53:39,773 - 60868 - ERROR - Activity Id : 5 - https://www.server_5.com/python/ - HTTPSConnectionPool(host='www.server_5.com', port=443): Max retries exceeded with url: /python/ (Caused by NewConnectionError('<urllib3.connection.HTTPSConnection object at 0x103263fa0>: Failed to establish a new connection: [Errno 8] nodename nor servname provided, or not known'))
2022-06-08 01:53:39,773 - 60868 - ERROR - Activity Id : 1 - https://www.server_5.com/python/ - HTTPSConnectionPool(host='www.server_5.com', port=443): Max retries exceeded with url: /python/ (Caused by NewConnectionError('<urllib3.connection.HTTPSConnection object at 0x103263820>: Failed to establish a new connection: [Errno 8] nodename nor servname provided, or not known'))
2022-06-08 01:53:39,773 - 60868 - ERROR - Activity Id : 1 - https://www.server_2.com/python/ - HTTPSConnectionPool(host='www.server_2.com', port=443): Max retries exceeded with url: /python/ (Caused by NewConnectionError('<urllib3.connection.HTTPSConnection object at 0x103257a30>: Failed to establish a new connection: [Errno 8] nodename nor servname provided, or not known'))
2022-06-08 01:53:39,773 - 60868 - ERROR - Activity Id : 5 - https://www.server_3.com/python/ - HTTPSConnectionPool(host='www.server_3.com', port=443): Max retries exceeded with url: /python/ (Caused by NewConnectionError('<urllib3.connection.HTTPSConnection object at 0x103263a00>: Failed to establish a new connection: [Errno 8] nodename nor servname provided, or not known'))
2022-06-08 01:53:39,773 - 60868 - ERROR - Activity Id : 3 - https://www.server_1.com/python/ - HTTPSConnectionPool(host='www.server_1.com', port=443): Max retries exceeded with url: /python/ (Caused by NewConnectionError('<urllib3.connection.HTTPSConnection object at 0x103257580>: Failed to establish a new connection: [Errno 8] nodename nor servname provided, or not known'))
2022-06-08 01:53:39,774 - 60868 - ERROR - Activity Id : 1 - https://www.server_3.com/python/ - HTTPSConnectionPool(host='www.server_3.com', port=443): Max retries exceeded with url: /python/ (Caused by NewConnectionError('<urllib3.connection.HTTPSConnection object at 0x103257dc0>: Failed to establish a new connection: [Errno 8] nodename nor servname provided, or not known'))
